<robot name="diff_robot">
    <link name="base_link">
        <visual>
            <geometry>
                <box size="0.8 0.7 0.1" />
            </geometry>
            <material name="LightGrey">
                <color rgba="0.7 0.7 0.7 1.0"/>
            </material>
        </visual>
        <collision>
            <geometry>
                <box size="0 0 0" />
            </geometry>
        </collision>
        <inertial>
            <mass value="0.0"/>
            <origin xyz="0.0 0.0 0.0" rpy="0.0 0.0 0.0"/>
            <inertia ixx="0.0" ixy="0.0" ixz="0.0" iyy="0.0" iyz="0.0" izz="0.0"/>
        </inertial>
    </link>

    <!-- Rear Right Wheel -->
    <link name="wheel_rear_right_link">
        <visual>
            <geometry>
                <cylinder radius="0.15" length="0.1"/>
            </geometry>
            <material name="Red">
                <color rgba="1. 0. 0. 1.9"/>
            </material>
        </visual>
        <collision>
            <geometry>
                <cylinder radius="0.15" length="0.1"/>
            </geometry>
        </collision>
        <inertial>
            <mass value="0.0"/>
            <origin xyz="0.0 0.0 0.0" rpy="0.0 0.0 0.0"/>
            <inertia ixx="0.0" ixy="0.0" ixz="0.0" iyy="0.0" iyz="0.0" izz="0.0"/>
        </inertial>
    </link>

    <joint name="wheel_rear_right_joint" type="continuous">
        <parent link="base_link"/>
        <child link="wheel_rear_right_link"/>
        <origin xyz="0.250 0.4 0" rpy="1.57 0 0"/>
        <axis xyz="0 0 0"/>
    </joint>
    
    <!-- Rear Left Wheel -->
    <link name="wheel_rear_left_link">
        <visual>
            <geometry>
                <cylinder radius="0.15" length="0.1"/>
            </geometry>
            <material name="Red">
                <color rgba="1. 0. 0. 1.9"/>
            </material>
        </visual>
        <collision>
            <geometry>
                <cylinder radius="0.15" length="0.1"/>
            </geometry>
        </collision>
        <inertial>
            <mass value="0.0"/>
            <origin xyz="0.0 0.0 0.0" rpy="0.0 0.0 0.0"/>
            <inertia ixx="0.0" ixy="0.0" ixz="0.0" iyy="0.0" iyz="0.0" izz="0.0"/>
        </inertial>
    </link>

    <joint name="wheel_rear_left_joint" type="continuous">
        <parent link="base_link"/>
        <child link="wheel_rear_left_link"/>
        <origin xyz="0.250 -0.4 0" rpy="1.57 0 0"/>
        <axis xyz="0 0 0"/>
    </joint>

</robot>